# -*- coding: utf-8 -*-
# Generated by Django 1.10.1 on 2017-04-02 19:22
from __future__ import unicode_literals

from django.db import migrations

"""
As Django's auto-generated migration creates it, the sequence
on ref_program_activity_id_seq is not "owned" by the corresponding
column; thus `repair_sequences` does not fix it, and primary key
errors result.
"""

class Migration(migrations.Migration):

    dependencies = [
        ('references', '0059_auto_20170330_2107'),
    ]

    operations = [
        migrations.RunSQL('''ALTER SEQUENCE
                             ref_program_activity_ref_program_activity_id_seq
                             OWNED BY
                             ref_program_activity.ref_program_activity_id_seq''',
                             migrations.RunSQL.noop)
    ]
